[ ERROR ] Error in file 'C:\TEST_SINAMOPE\TEST\recursos.robot': Importing test library 'C:\TEST_SINAMOPE\TEST\ReadData.py' failed: FileNotFoundError: [Errno 2] No such file or directory: 'Datos_sinamope.xlsx'
Traceback (most recent call last):
  File "C:\TEST_SINAMOPE\TEST\ReadData.py", line 3, in <module>
    data=openpyxl.load_workbook("Datos_sinamope.xlsx")
  File "c:\users\rodrigo.villanueva.c\appdata\local\programs\python\python37\lib\site-packages\openpyxl\reader\excel.py", line 313, in load_workbook
    data_only, keep_links)
  File "c:\users\rodrigo.villanueva.c\appdata\local\programs\python\python37\lib\site-packages\openpyxl\reader\excel.py", line 124, in __init__
    self.archive = _validate_archive(fn)
  File "c:\users\rodrigo.villanueva.c\appdata\local\programs\python\python37\lib\site-packages\openpyxl\reader\excel.py", line 96, in _validate_archive
    archive = ZipFile(filename, 'r')
  File "c:\users\rodrigo.villanueva.c\appdata\local\programs\python\python37\lib\zipfile.py", line 1240, in __init__
    self.fp = io.open(file, filemode)
PYTHONPATH:
  C:\Users\rodrigo.villanueva.c\AppData\Local\Programs\Python\Python37\Scripts\robot.exe
  c:\users\rodrigo.villanueva.c\appdata\local\programs\python\python37\python37.zip
  c:\users\rodrigo.villanueva.c\appdata\local\programs\python\python37\DLLs
  c:\users\rodrigo.villanueva.c\appdata\local\programs\python\python37\lib
  c:\users\rodrigo.villanueva.c\appdata\local\programs\python\python37
  c:\users\rodrigo.villanueva.c\appdata\local\programs\python\python37\lib\site-packages
